{"uuid": "622b333e-5c73-401a-b80a-79b45828e8f0", "children": ["79c42711-0566-478e-a843-54d04bb4dd19"], "befores": [{"name": "mobile_management", "status": "broken", "statusDetails": {"message": "pydantic_core._pydantic_core.ValidationError: 5 validation errors for Config\nREMOTE_URL\n  Input should be a valid string [type=string_type, input_value=None, input_type=NoneType]\n    For further information visit https://errors.pydantic.dev/2.7/v/string_type\nPLATFORM_NAME\n  Input should be a valid string [type=string_type, input_value=None, input_type=NoneType]\n    For further information visit https://errors.pydantic.dev/2.7/v/string_type\nDEVICE_NAME\n  Input should be a valid string [type=string_type, input_value=None, input_type=NoneType]\n    For further information visit https://errors.pydantic.dev/2.7/v/string_type\nAPP_WAIT_ACTIVITY\n  Input should be a valid string [type=string_type, input_value=None, input_type=NoneType]\n    For further information visit https://errors.pydantic.dev/2.7/v/string_type\nAPP\n  Input should be a valid string [type=string_type, input_value=None, input_type=NoneType]\n    For further information visit https://errors.pydantic.dev/2.7/v/string_type\n", "trace": "  File \"/Users/bella/projects/qa_guru_10.22/.venv/lib/python3.9/site-packages/pluggy/_callers.py\", line 167, in _multicall\n    teardown.throw(outcome._exception)\n  File \"/Users/bella/projects/qa_guru_10.22/.venv/lib/python3.9/site-packages/_pytest/setuponly.py\", line 36, in pytest_fixture_setup\n    return (yield)\n  File \"/Users/bella/projects/qa_guru_10.22/.venv/lib/python3.9/site-packages/pluggy/_callers.py\", line 103, in _multicall\n    res = hook_impl.function(*args)\n  File \"/Users/bella/projects/qa_guru_10.22/.venv/lib/python3.9/site-packages/_pytest/fixtures.py\", line 1132, in pytest_fixture_setup\n    result = call_fixture_func(fixturefunc, request, kwargs)\n  File \"/Users/bella/projects/qa_guru_10.22/.venv/lib/python3.9/site-packages/_pytest/fixtures.py\", line 906, in call_fixture_func\n    fixture_result = next(generator)\n  File \"/Users/bella/projects/qa_guru_10.22/tests_app/conftest.py\", line 22, in mobile_management\n    from config import config_app\n  File \"/Users/bella/projects/qa_guru_10.22/config.py\", line 50, in <module>\n    config_app = Config()\n  File \"/Users/bella/projects/qa_guru_10.22/.venv/lib/python3.9/site-packages/pydantic_settings/main.py\", line 84, in __init__\n    super().__init__(\n  File \"/Users/bella/projects/qa_guru_10.22/.venv/lib/python3.9/site-packages/pydantic/main.py\", line 175, in __init__\n    self.__pydantic_validator__.validate_python(data, self_instance=self)\n"}, "start": 1713882502685, "stop": 1713882502965}], "start": 1713882502685, "stop": 1713882503094}