{"name": "test_search", "status": "broken", "statusDetails": {"message": "pydantic_core._pydantic_core.ValidationError: 5 validation errors for Config\nREMOTE_URL\n  Input should be a valid string [type=string_type, input_value=None, input_type=NoneType]\n    For further information visit https://errors.pydantic.dev/2.7/v/string_type\nPLATFORM_NAME\n  Input should be a valid string [type=string_type, input_value=None, input_type=NoneType]\n    For further information visit https://errors.pydantic.dev/2.7/v/string_type\nDEVICE_NAME\n  Input should be a valid string [type=string_type, input_value=None, input_type=NoneType]\n    For further information visit https://errors.pydantic.dev/2.7/v/string_type\nAPP_WAIT_ACTIVITY\n  Input should be a valid string [type=string_type, input_value=None, input_type=NoneType]\n    For further information visit https://errors.pydantic.dev/2.7/v/string_type\nAPP\n  Input should be a valid string [type=string_type, input_value=None, input_type=NoneType]\n    For further information visit https://errors.pydantic.dev/2.7/v/string_type", "trace": "request = <SubRequest 'mobile_management' for <Function test_search>>\n\n    @pytest.fixture(scope='function', autouse=True)\n    def mobile_management(request):\n>       from config import config_app\n\nconftest.py:22: \n_ _ _ _ _ _ _ _ _ _ _ _ _ _ _ _ _ _ _ _ _ _ _ _ _ _ _ _ _ _ _ _ _ _ _ _ _ _ _ _ \n../config.py:50: in <module>\n    config_app = Config()\n_ _ _ _ _ _ _ _ _ _ _ _ _ _ _ _ _ _ _ _ _ _ _ _ _ _ _ _ _ _ _ _ _ _ _ _ _ _ _ _ \n\n__pydantic_self__ = Config(), _case_sensitive = None, _env_prefix = None\n_env_file = PosixPath('.'), _env_file_encoding = None, _env_ignore_empty = None\n_env_nested_delimiter = None, _env_parse_none_str = None, _secrets_dir = None\nvalues = {}\n\n    def __init__(\n        __pydantic_self__,\n        _case_sensitive: bool | None = None,\n        _env_prefix: str | None = None,\n        _env_file: DotenvType | None = ENV_FILE_SENTINEL,\n        _env_file_encoding: str | None = None,\n        _env_ignore_empty: bool | None = None,\n        _env_nested_delimiter: str | None = None,\n        _env_parse_none_str: str | None = None,\n        _secrets_dir: str | Path | None = None,\n        **values: Any,\n    ) -> None:\n        # Uses something other than `self` the first arg to allow \"self\" as a settable attribute\n>       super().__init__(\n            **__pydantic_self__._settings_build_values(\n                values,\n                _case_sensitive=_case_sensitive,\n                _env_prefix=_env_prefix,\n                _env_file=_env_file,\n                _env_file_encoding=_env_file_encoding,\n                _env_ignore_empty=_env_ignore_empty,\n                _env_nested_delimiter=_env_nested_delimiter,\n                _env_parse_none_str=_env_parse_none_str,\n                _secrets_dir=_secrets_dir,\n            )\n        )\nE       pydantic_core._pydantic_core.ValidationError: 5 validation errors for Config\nE       REMOTE_URL\nE         Input should be a valid string [type=string_type, input_value=None, input_type=NoneType]\nE           For further information visit https://errors.pydantic.dev/2.7/v/string_type\nE       PLATFORM_NAME\nE         Input should be a valid string [type=string_type, input_value=None, input_type=NoneType]\nE           For further information visit https://errors.pydantic.dev/2.7/v/string_type\nE       DEVICE_NAME\nE         Input should be a valid string [type=string_type, input_value=None, input_type=NoneType]\nE           For further information visit https://errors.pydantic.dev/2.7/v/string_type\nE       APP_WAIT_ACTIVITY\nE         Input should be a valid string [type=string_type, input_value=None, input_type=NoneType]\nE           For further information visit https://errors.pydantic.dev/2.7/v/string_type\nE       APP\nE         Input should be a valid string [type=string_type, input_value=None, input_type=NoneType]\nE           For further information visit https://errors.pydantic.dev/2.7/v/string_type\n\n../.venv/lib/python3.9/site-packages/pydantic_settings/main.py:84: ValidationError"}, "start": 1713882502682, "stop": 1713882502682, "uuid": "79c42711-0566-478e-a843-54d04bb4dd19", "historyId": "b6b565c2411c409b861991c2a673946c", "testCaseId": "b6b565c2411c409b861991c2a673946c", "fullName": "tests_app.test_android_wikipedia#test_search", "labels": [{"name": "parentSuite", "value": "tests_app"}, {"name": "suite", "value": "test_android_wikipedia"}, {"name": "host", "value": "MacBook-Pro-Admin.local"}, {"name": "thread", "value": "48635-MainThread"}, {"name": "framework", "value": "pytest"}, {"name": "language", "value": "cpython3"}, {"name": "package", "value": "tests_app.test_android_wikipedia"}]}